Workbook

Sheet New
A1: COUNTRY.ID | B1: COUNTRY | C1: GPH
A2: G110 | B2: Advanced Economies | C2: =IFERROR(IF(VLOOKUP(B2,Old!$A:$B,2,FALSE)="","",VLOOKUP(B2,Old!$A:$B,2,FALSE)),"Non trouvé")
A3: AFG | B3: Afghanistan, Islamic Republic of | C3: 700 | E3: Legend: | F3: OK
A4: GX605 | B4: Africa | C4: =IFERROR(IF(VLOOKUP(B4,Old!$A:$B,2,FALSE)="","",VLOOKUP(B4,Old!$A:$B,2,FALSE)),"Non trouvé") | F4: Two entities
A5: TX799 | B5: Africa not specified | C5: =IFERROR(IF(VLOOKUP(B5,Old!$A:$B,2,FALSE)="","",VLOOKUP(B5,Old!$A:$B,2,FALSE)),"Non trouvé")
A6: ALB | B6: Albania | C6: =IFERROR(IF(VLOOKUP(B6,Old!$A:$B,2,FALSE)="","",VLOOKUP(B6,Old!$A:$B,2,FALSE)),"Non trouvé") -> 339
A7: DZA | B7: Algeria | C7: =IFERROR(IF(VLOOKUP(B7,Old!$A:$B,2,FALSE)="","",VLOOKUP(B7,Old!$A:$B,2,FALSE)),"Non trouvé") -> 615
A8: ASM | B8: American Samoa | C8: =IFERROR(IF(VLOOKUP(B8,Old!$A:$B,2,FALSE)="","",VLOOKUP(B8,Old!$A:$B,2,FALSE)),"Non trouvé") -> 991
A9: AGO | B9: Angola | C9: =IFERROR(IF(VLOOKUP(B9,Old!$A:$B,2,FALSE)="","",VLOOKUP(B9,Old!$A:$B,2,FALSE)),"Non trouvé") -> 540
A10: AIA | B10: Anguilla, United Kingdom-British Overseas Territory | C10: 1062
A11: ATG | B11: Antigua and Barbuda | C11: =IFERROR(IF(VLOOKUP(B11,Old!$A:$B,2,FALSE)="","",VLOOKUP(B11,Old!$A:$B,2,FALSE)),"Non trouvé") -> 58
A12: ARG | B12: Argentina | C12: =IFERROR(IF(VLOOKUP(B12,Old!$A:$B,2,FALSE)="","",VLOOKUP(B12,Old!$A:$B,2,FALSE)),"Non trouvé") -> 160
A13: ARM | B13: Armenia, Republic of | C13: 371
A14: ABW | B14: Aruba, Kingdom of the Netherlands | C14: =IFERROR(IF(VLOOKUP(B14,Old!$A:$B,2,FALSE)="","",VLOOKUP(B14,Old!$A:$B,2,FALSE)),"Non trouvé") -> 1069
A15: TX598 | B15: Asia not specified | C15: =IFERROR(IF(VLOOKUP(B15,Old!$A:$B,2,FALSE)="","",VLOOKUP(B15,Old!$A:$B,2,FALSE)),"Non trouvé")
A16: AUS | B16: Australia | C16: =IFERROR(IF(VLOOKUP(B16,Old!$A:$B,2,FALSE)="","",VLOOKUP(B16,Old!$A:$B,2,FALSE)),"Non trouvé") -> 900
A17: AUT | B17: Austria | C17: =IFERROR(IF(VLOOKUP(B17,Old!$A:$B,2,FALSE)="","",VLOOKUP(B17,Old!$A:$B,2,FALSE)),"Non trouvé") -> 305
A18: AZE | B18: Azerbaijan, Republic of | C18: 373
A19: BHS | B19: Bahamas, The | C19: =IFERROR(IF(VLOOKUP(B19,Old!$A:$B,2,FALSE)="","",VLOOKUP(B19,Old!$A:$B,2,FALSE)),"Non trouvé") -> 31
A20: BHR | B20: Bahrain, Kingdom of | C20: =IFERROR(IF(VLOOKUP(B20,Old!$A:$B,2,FALSE)="","",VLOOKUP(B20,Old!$A:$B,2,FALSE)),"Non trouvé") -> 692
A21: BGD | B21: Bangladesh | C21: =IFERROR(IF(VLOOKUP(B21,Old!$A:$B,2,FALSE)="","",VLOOKUP(B21,Old!$A:$B,2,FALSE)),"Non trouvé") -> 771
A22: BRB | B22: Barbados | C22: =IFERROR(IF(VLOOKUP(B22,Old!$A:$B,2,FALSE)="","",VLOOKUP(B22,Old!$A:$B,2,FALSE)),"Non trouvé") -> 53
A23: BLR | B23: Belarus, Republic of | C23: 370
A24: BEL | B24: Belgium | C24: =IFERROR(IF(VLOOKUP(B24,Old!$A:$B,2,FALSE)="","",VLOOKUP(B24,Old!$A:$B,2,FALSE)),"Non trouvé") -> 211
A25: TX126 | B25: Belgium-Luxembourg | C25: =IFERROR(IF(VLOOKUP(B25,Old!$A:$B,2,FALSE)="","",VLOOKUP(B25,Old!$A:$B,2,FALSE)),"Non trouvé")
A26: BLZ | B26: Belize | C26: =IFERROR(IF(VLOOKUP(B26,Old!$A:$B,2,FALSE)="","",VLOOKUP(B26,Old!$A:$B,2,FALSE)),"Non trouvé") -> 80
A27: BEN | B27: Benin | C27: =IFERROR(IF(VLOOKUP(B27,Old!$A:$B,2,FALSE)="","",VLOOKUP(B27,Old!$A:$B,2,FALSE)),"Non trouvé") -> 434
A28: BMU | B28: Bermuda | C28: =IFERROR(IF(VLOOKUP(B28,Old!$A:$B,2,FALSE)="","",VLOOKUP(B28,Old!$A:$B,2,FALSE)),"Non trouvé") -> 30
A29: BTN | B29: Bhutan | C29: =IFERROR(IF(VLOOKUP(B29,Old!$A:$B,2,FALSE)="","",VLOOKUP(B29,Old!$A:$B,2,FALSE)),"Non trouvé") -> 760
A30: BOL | B30: Bolivia | C30: =IFERROR(IF(VLOOKUP(B30,Old!$A:$B,2,FALSE)="","",VLOOKUP(B30,Old!$A:$B,2,FALSE)),"Non trouvé") -> 145
A31: BIH | B31: Bosnia and Herzegovina | C31: =IFERROR(IF(VLOOKUP(B31,Old!$A:$B,2,FALSE)="","",VLOOKUP(B31,Old!$A:$B,2,FALSE)),"Non trouvé") -> 346
A32: BWA | B32: Botswana | C32: =IFERROR(IF(VLOOKUP(B32,Old!$A:$B,2,FALSE)="","",VLOOKUP(B32,Old!$A:$B,2,FALSE)),"Non trouvé") -> 571
A33: BRA | B33: Brazil | C33: =IFERROR(IF(VLOOKUP(B33,Old!$A:$B,2,FALSE)="","",VLOOKUP(B33,Old!$A:$B,2,FALSE)),"Non trouvé") -> 140
A34: BRN | B34: Brunei Darussalam | C34: =IFERROR(IF(VLOOKUP(B34,Old!$A:$B,2,FALSE)="","",VLOOKUP(B34,Old!$A:$B,2,FALSE)),"Non trouvé") -> 835
A35: BGR | B35: Bulgaria | C35: =IFERROR(IF(VLOOKUP(B35,Old!$A:$B,2,FALSE)="","",VLOOKUP(B35,Old!$A:$B,2,FALSE)),"Non trouvé") -> 355
... A42: CAN | B42: Canada | C42: =IFERROR(IF(VLOOKUP(B42,Old!$A:$B,2,FALSE)="","",VLOOKUP(B42,Old!$A:$B,2,FALSE)),"Non trouvé") -> 20
A43: CAF | B43: Central African Republic | C43: 482
A44: TCD | B44: Chad | C44: =IFERROR(IF(VLOOKUP(B44,Old!$A:$B,2,FALSE)="","",VLOOKUP(B44,Old!$A:$B,2,FALSE)),"Non trouvé") -> 483
A45: CHL | B45: Chile | C45: =IFERROR(IF(VLOOKUP(B45,Old!$A:$B,2,FALSE)="","",VLOOKUP(B45,Old!$A:$B,2,FALSE)),"Non trouvé") -> 155
A46: CHN | B46: China, People's Republic of | C46: 710
...

Sheet Old
A1: Country.Name | B1: GPH
A2: Advanced Economies
A3: Afghanistan, Islamic Rep. of | B3: 700
A4: Africa
A5: Africa not specified
A6: Albania | B6: 339
A7: Algeria | B7: 615
A8: American Samoa | B8: 991
A9: Angola | B9: 540
A10: Anguilla | B10: 1062
A11: Antigua and Barbuda | B11: 58
A12: Argentina | B12: 160
A13: Armenia, Rep. of | B13: 371
A14: Aruba, Kingdom of the Netherlands | B14: 1069
A15: Asia not specified
A16: Australia | B16: 900
A17: Austria | B17: 305
A18: Azerbaijan, Rep. of | B18: 373
A19: Bahamas, The | B19: 31
A20: Bahrain, Kingdom of | B20: 692
A21: Bangladesh | B21: 771
A22: Barbados | B22: 53
A23: Belarus, Rep. of | B23: 370
A24: Belgium | B24: 211
A25: Belgium-Luxembourg
A26: Belize | B26: 80
A27: Benin | B27: 434
A28: Bermuda | B28: 30
A29: Bhutan | B29: 760
A30: Bolivia | B30: 145
A31: Bosnia and Herzegovina | B31: 346
A32: Botswana | B32: 571
A33: Brazil | B33: 140
A34: Brunei Darussalam | B34: 835
A35: Bulgaria | B35: 355
A36: Burkina Faso | B36: 439
A37: Burundi | B37: 516
... A47: China, P.R.: Mainland | B47: 710
A48: CIS
A49: Colombia | B49: 100
...
